<?xml version="1.0"?>
<robot xmlns:xacro="http://www.ros.org/wiki/xacro" name="scout_mini">

  <xacro:property name="PI" value="3.1415926535897931" />

  <!-- Base link -->
  <link name="base_link">
    <visual>
      <origin xyz="0 0 0.0" rpy="${PI/2} 0 -${PI/2}" />
      <geometry>
        <mesh filename="file:///apollo_ws/install/scout_mini_description/share/scout_mini_description/meshes/body.dae" />
      </geometry>
    </visual>
    <collision>
      <origin xyz="0 0 0" rpy="0 0 0" />
      <geometry>
        <box size="0.514618 0.3816 0.10357" />
      </geometry>
    </collision>
  </link>

  <!-- LiDAR link -->
  <link name="laser_link">
    <visual>
      <geometry>
        <cylinder radius="0.05" length="0.04"/>
      </geometry>
    </visual>
    <collision>
      <geometry>
        <cylinder radius="0.05" length="0.04"/>
      </geometry>
    </collision>
    <inertial>
      <mass value="0.1"/>
      <origin xyz="0 0 0" rpy="0 0 0"/>
      <inertia ixx="1e-4" ixy="0" ixz="0" iyy="1e-4" iyz="0" izz="1e-4"/>
    </inertial>
  </link>

  <joint name="laser_joint" type="fixed">
    <parent link="base_link"/>
    <child link="laser_link"/>
    <origin xyz="0.1 0 0.46" rpy="0 0 0"/>
  </joint>

  <joint name="inertial_joint" type="fixed">
    <parent link="base_link" />
    <child link="inertial_link" />
    <origin xyz="0 0 0" rpy="0 0 0" />
  </joint>

  <link name="inertial_link">
    <inertial>
      <mass value="60" />
      <origin xyz="0 0 0" rpy="0 0 0" />
      <inertia ixx="2.288641" ixy="0" ixz="0" iyy="5.103976" iyz="0" izz="3.431465" />
    </inertial>
  </link>

  <joint name="front_left_wheel_joint" type="continuous">
    <parent link="base_link" />
    <child link="front_left_wheel_link" />
    <origin xyz="0.2319755 0.245 -0.100998" rpy="0 0 0" />
    <axis xyz="0 1 0" rpy="0 0 0" />
  </joint>

  <link name="front_left_wheel_link">
    <visual>
      <origin xyz="0 -0.0367485 0" rpy="-${PI/2} 0 0" />
      <geometry>
        <mesh filename="file:///apollo_ws/install/scout_mini_description/share/scout_mini_description/meshes/tire.dae" />
      </geometry>
    </visual>
    <collision>
      <origin xyz="0 0 0" rpy="${PI/2} 0 0" />
      <geometry>
        <cylinder radius="0.0875" length="0.08" />
      </geometry>
    </collision>
    <inertial>
      <mass value="2.637" />
      <origin xyz="0 0 0" rpy="0 0 0" />
      <inertia ixx="0.02467" ixy="0" ixz="0" iyy="0.04411" iyz="0" izz="0.02467" />
    </inertial>
  </link>

  <joint name="rear_left_wheel_joint" type="continuous">
    <parent link="base_link" />
    <child link="rear_left_wheel_link" />
    <origin xyz="-0.2319755 0.245 -0.100998" rpy="0 0 0" />
    <axis xyz="0 1 0" rpy="0 0 0" />
  </joint>

  <link name="rear_left_wheel_link">
    <visual>
      <origin xyz="0 -0.0367485 0" rpy="-${PI/2} 0 0" />
      <geometry>
        <mesh filename="file:///apollo_ws/install/scout_mini_description/share/scout_mini_description/meshes/tire.dae" />
      </geometry>
    </visual>
    <collision>
      <origin xyz="0 0 0" rpy="${PI/2} 0 0" />
      <geometry>
        <cylinder radius="0.0875" length="0.08" />
      </geometry>
    </collision>
    <inertial>
      <mass value="2.637" />
      <origin xyz="0 0 0" rpy="0 0 0" />
      <inertia ixx="0.02467" ixy="0" ixz="0" iyy="0.04411" iyz="0" izz="0.02467" />
    </inertial>
  </link>

  <joint name="front_right_wheel_joint" type="continuous">
    <parent link="base_link" />
    <child link="front_right_wheel_link" />
    <origin xyz="0.2319755 -0.245 -0.100998" rpy="0 0 0" />
    <axis xyz="0 1 0" rpy="0 0 0" />
  </joint>

  <link name="front_right_wheel_link">
    <visual>
      <origin xyz="0 0.0367485 0" rpy="${PI/2} 0 0" />
      <geometry>
        <mesh filename="file:///apollo_ws/install/scout_mini_description/share/scout_mini_description/meshes/tire.dae" />
      </geometry>
    </visual>
    <collision>
      <origin xyz="0 0 0" rpy="${PI/2} 0 0" />
      <geometry>
        <cylinder radius="0.0875" length="0.08" />
      </geometry>
    </collision>
    <inertial>
      <mass value="2.637" />
      <origin xyz="0 0 0" rpy="0 0 0" />
      <inertia ixx="0.02467" ixy="0" ixz="0" iyy="0.04411" iyz="0" izz="0.02467" />
    </inertial>
  </link>

  <joint name="rear_right_wheel_joint" type="continuous">
    <parent link="base_link" />
    <child link="rear_right_wheel_link" />
    <origin xyz="-0.2319755 -0.245 -0.100998" rpy="0 0 0" />
    <axis xyz="0 1 0" rpy="0 0 0" />
  </joint>

  <link name="rear_right_wheel_link">
    <visual>
      <origin xyz="0 0.0367485 0" rpy="${PI/2} 0 0" />
      <geometry>
        <mesh filename="file:///apollo_ws/install/scout_mini_description/share/scout_mini_description/meshes/tire.dae" />
      </geometry>
    </visual>
    <collision>
      <origin xyz="0 0 0" rpy="${PI/2} 0 0" />
      <geometry>
        <cylinder radius="0.0875" length="0.08" />
      </geometry>
    </collision>
    <inertial>
      <mass value="2.637" />
      <origin xyz="0 0 0" rpy="0 0 0" />
      <inertia ixx="0.02467" ixy="0" ixz="0" iyy="0.04411" iyz="0" izz="0.02467" />
    </inertial>
  </link>

  <!-- Hardware interface for REAL ROBOT -->
  <ros2_control name="scout_mini_control" type="system">
    <hardware>
      <plugin>scout_mini_hardware/ScoutMiniHardware</plugin>
      <param name="interface">can0</param>
      <param name="wheel_radius">0.0875</param>
      <param name="wheel_separation">0.490</param>
    </hardware>
    <joint name="front_left_wheel_joint">
      <command_interface name="velocity">
        <param name="min">-1</param>
        <param name="max">1</param>
      </command_interface>
      <state_interface name="position" />
      <state_interface name="velocity" />
      <state_interface name="effort" />
    </joint>
    <joint name="rear_left_wheel_joint">
      <command_interface name="velocity">
        <param name="min">-1</param>
        <param name="max">1</param>
      </command_interface>
      <state_interface name="position" />
      <state_interface name="velocity" />
      <state_interface name="effort" />
    </joint>
    <joint name="front_right_wheel_joint">
      <command_interface name="velocity">
        <param name="min">-1</param>
        <param name="max">1</param>
      </command_interface>
      <state_interface name="position" />
      <state_interface name="velocity" />
      <state_interface name="effort" />
    </joint>
    <joint name="rear_right_wheel_joint">
      <command_interface name="velocity">
        <param name="min">-1</param>
        <param name="max">1</param>
      </command_interface>
      <state_interface name="position" />
      <state_interface name="velocity" />
      <state_interface name="effort" />
    </joint>
  </ros2_control>

  <!-- ========== GAZEBO PLUGINS ========== -->

  <!-- Gazebo LiDAR Sensor Plugin -->
  <gazebo reference="laser_link">
    <sensor name="lidar_sensor" type="ray">
      <always_on>true</always_on>
      <update_rate>10</update_rate>
      <visualize>true</visualize>
      <ray>
        <scan>
          <horizontal>
            <samples>720</samples>
            <resolution>1</resolution>
            <min_angle>-3.14159</min_angle>
            <max_angle>3.14159</max_angle>
          </horizontal>
        </scan>
        <range>
          <min>0.1</min>
          <max>30.0</max>
          <resolution>0.01</resolution>
        </range>
      </ray>
      <plugin name="gazebo_ros_laser_controller" filename="libgazebo_ros_ray_sensor.so">
        <ros>
          <remapping>~/out:=scan</remapping>
        </ros>
        <output_type>sensor_msgs/LaserScan</output_type>
        <frame_name>laser_link</frame_name>
      </plugin>
    </sensor>
  </gazebo>

  <!-- Differential Drive Controller Plugin for Gazebo -->
  <gazebo>
    <plugin name="differential_drive_controller" filename="libgazebo_ros_diff_drive.so">
      <update_rate>50</update_rate>
      <left_joint>front_left_wheel_joint</left_joint>
      <right_joint>front_right_wheel_joint</right_joint>
      <wheel_separation>0.490</wheel_separation>
      <wheel_diameter>0.175</wheel_diameter>
      <max_wheel_torque>20</max_wheel_torque>
      <max_wheel_acceleration>1.0</max_wheel_acceleration>
      <command_topic>cmd_vel</command_topic>
      <odometry_topic>odom</odometry_topic>
      <odometry_frame>odom</odometry_frame>
      <robot_base_frame>base_link</robot_base_frame>
      <publish_odom>true</publish_odom>
      <publish_odom_tf>true</publish_odom_tf>
      <publish_wheel_tf>false</publish_wheel_tf>
      <odometry_source>world</odometry_source>
      <command_timeout>0.5</command_timeout>
    </plugin>
  </gazebo>

  <!-- Joint State Publisher Plugin for Gazebo -->
  <gazebo>
    <plugin name="gazebo_ros_joint_state_publisher" filename="libgazebo_ros_joint_state_publisher.so">
      <update_rate>50</update_rate>
      <joint_name>front_left_wheel_joint</joint_name>
      <joint_name>front_right_wheel_joint</joint_name>
      <joint_name>rear_left_wheel_joint</joint_name>
      <joint_name>rear_right_wheel_joint</joint_name>
    </plugin>
  </gazebo>

  <!-- Gazebo material colors for better visualization -->
  <gazebo reference="base_link">
    <material>Gazebo/DarkGrey</material>
  </gazebo>

  <gazebo reference="front_left_wheel_link">
    <material>Gazebo/Black</material>
  </gazebo>

  <gazebo reference="front_right_wheel_link">
    <material>Gazebo/Black</material>
  </gazebo>

  <gazebo reference="rear_left_wheel_link">
    <material>Gazebo/Black</material>
  </gazebo>

  <gazebo reference="rear_right_wheel_link">
    <material>Gazebo/Black</material>
  </gazebo>

  <gazebo reference="laser_link">
    <material>Gazebo/Blue</material>
  </gazebo>

</robot>