<?xml version="1.0"?>
<robot xmlns:xacro="http://www.ros.org/wiki/xacro" name="scout_mini">

  <xacro:property name="PI" value="3.1415926535897931" />

  <!-- Base link -->
  <link name="base_link">
    <visual>
      <origin xyz="0 0 0.0" rpy="${PI/2} 0 -${PI/2}" />
      <geometry>
        <mesh filename="package://scout_mini_description/meshes/body.dae" />
      </geometry>
    </visual>
    <collision>
      <origin xyz="0 0 0" rpy="0 0 0" />
      <geometry>
        <box size="0.514618 0.3816 0.10357" />
      </geometry>
    </collision>
  </link>

  <!-- LiDAR link -->
  <link name="laser_link">
    <visual>
      <geometry>
        <cylinder radius="0.05" length="0.04"/>
      </geometry>
      <material name="black">
        <color rgba="0.1 0.1 0.1 1"/>
      </material>
    </visual>
    <collision>
      <geometry>
        <cylinder radius="0.05" length="0.04"/>
      </geometry>
    </collision>
    <inertial>
      <mass value="0.1"/>
      <origin xyz="0 0 0" rpy="0 0 0"/>
      <inertia ixx="1e-4" ixy="0" ixz="0" iyy="1e-4" iyz="0" izz="1e-4"/>
    </inertial>
  </link>

  <joint name="laser_joint" type="fixed">
    <parent link="base_link"/>
    <child link="laser_link"/>
    <origin xyz="0.1 0 0.46" rpy="0 0 0"/>
  </joint>

  <!-- Inertial link -->
  <joint name="inertial_joint" type="fixed">
    <parent link="base_link" />
    <child link="inertial_link" />
    <origin xyz="0 0 0" rpy="0 0 0" />
  </joint>

  <link name="inertial_link">
    <inertial>
      <mass value="60" />
      <origin xyz="0 0 0" rpy="0 0 0" />
      <inertia ixx="2.288641" ixy="0" ixz="0" iyy="5.103976" iyz="0" izz="3.431465" />
    </inertial>
  </link>

  <!-- Wheels -->
  <joint name="front_left_wheel_joint" type="continuous">
    <parent link="base_link" />
    <child link="front_left_wheel_link" />
    <origin xyz="0.2319755 0.245 -0.100998" rpy="0 0 0" />
    <axis xyz="0 1 0" rpy="0 0 0" />
  </joint>

  <link name="front_left_wheel_link">
    <visual>
      <origin xyz="0 -0.0367485 0" rpy="-${PI/2} 0 0" />
      <geometry>
        <mesh filename="package://scout_mini_description/meshes/tire.dae" />
      </geometry>
    </visual>
    <collision>
      <origin xyz="0 0 0" rpy="${PI/2} 0 0" />
      <geometry>
        <cylinder radius="0.0875" length="0.08" />
      </geometry>
    </collision>
    <inertial>
      <mass value="2.637" />
      <origin xyz="0 0 0" rpy="0 0 0" />
      <inertia ixx="0.02467" ixy="0" ixz="0" iyy="0.04411" iyz="0" izz="0.02467" />
    </inertial>
  </link>

  <joint name="rear_left_wheel_joint" type="continuous">
    <parent link="base_link" />
    <child link="rear_left_wheel_link" />
    <origin xyz="-0.2319755 0.245 -0.100998" rpy="0 0 0" />
    <axis xyz="0 1 0" rpy="0 0 0" />
  </joint>

  <link name="rear_left_wheel_link">
    <visual>
      <origin xyz="0 -0.0367485 0" rpy="-${PI/2} 0 0" />
      <geometry>
        <mesh filename="package://scout_mini_description/meshes/tire.dae" />
      </geometry>
    </visual>
    <collision>
      <origin xyz="0 0 0" rpy="${PI/2} 0 0" />
      <geometry>
        <cylinder radius="0.0875" length="0.08" />
      </geometry>
    </collision>
    <inertial>
      <mass value="2.637" />
      <origin xyz="0 0 0" rpy="0 0 0" />
      <inertia ixx="0.02467" ixy="0" ixz="0" iyy="0.04411" iyz="0" izz="0.02467" />
    </inertial>
  </link>

  <joint name="front_right_wheel_joint" type="continuous">
    <parent link="base_link" />
    <child link="front_right_wheel_link" />
    <origin xyz="0.2319755 -0.245 -0.100998" rpy="0 0 0" />
    <axis xyz="0 1 0" rpy="0 0 0" />
  </joint>

  <link name="front_right_wheel_link">
    <visual>
      <origin xyz="0 0.0367485 0" rpy="${PI/2} 0 0" />
      <geometry>
        <mesh filename="package://scout_mini_description/meshes/tire.dae" />
      </geometry>
    </visual>
    <collision>
      <origin xyz="0 0 0" rpy="${PI/2} 0 0" />
      <geometry>
        <cylinder radius="0.0875" length="0.08" />
      </geometry>
    </collision>
    <inertial>
      <mass value="2.637" />
      <origin xyz="0 0 0" rpy="0 0 0" />
      <inertia ixx="0.02467" ixy="0" ixz="0" iyy="0.04411" iyz="0" izz="0.02467" />
    </inertial>
  </link>

  <joint name="rear_right_wheel_joint" type="continuous">
    <parent link="base_link" />
    <child link="rear_right_wheel_link" />
    <origin xyz="-0.2319755 -0.245 -0.100998" rpy="0 0 0" />
    <axis xyz="0 1 0" rpy="0 0 0" />
  </joint>

  <link name="rear_right_wheel_link">
    <visual>
      <origin xyz="0 0.0367485 0" rpy="${PI/2} 0 0" />
      <geometry>
        <mesh filename="package://scout_mini_description/meshes/tire.dae" />
      </geometry>
    </visual>
    <collision>
      <origin xyz="0 0 0" rpy="${PI/2} 0 0" />
      <geometry>
        <cylinder radius="0.0875" length="0.08" />
      </geometry>
    </collision>
    <inertial>
      <mass value="2.637" />
      <origin xyz="0 0 0" rpy="0 0 0" />
      <inertia ixx="0.02467" ixy="0" ixz="0" iyy="0.04411" iyz="0" izz="0.02467" />
    </inertial>
  </link>

  <!-- Gazebo-specific ros2_control -->
  <ros2_control name="scout_mini_control" type="system">
    <hardware>
      <plugin>gazebo_ros2_control/GazeboSystem</plugin>
    </hardware>
    <joint name="front_left_wheel_joint">
      <command_interface name="velocity">
        <param name="min">-1</param>
        <param name="max">1</param>
      </command_interface>
      <state_interface name="position" />
      <state_interface name="velocity" />
      <state_interface name="effort" />
    </joint>
    <joint name="rear_left_wheel_joint">
      <command_interface name="velocity">
        <param name="min">-1</param>
        <param name="max">1</param>
      </command_interface>
      <state_interface name="position" />
      <state_interface name="velocity" />
      <state_interface name="effort" />
    </joint>
    <joint name="front_right_wheel_joint">
      <command_interface name="velocity">
        <param name="min">-1</param>
        <param name="max">1</param>
      </command_interface>
      <state_interface name="position" />
      <state_interface name="velocity" />
      <state_interface name="effort" />
    </joint>
    <joint name="rear_right_wheel_joint">
      <command_interface name="velocity">
        <param name="min">-1</param>
        <param name="max">1</param>
      </command_interface>
      <state_interface name="position" />
      <state_interface name="velocity" />
      <state_interface name="effort" />
    </joint>
  </ros2_control>

  <!-- Gazebo ros2_control plugin -->
  <gazebo>
    <plugin filename="libgazebo_ros2_control.so" name="gazebo_ros2_control">
      <parameters>/apollo_ws/src/scout_mini_base/config/scout_mini.yaml</parameters>
    </plugin>
  </gazebo>

  <!-- Gazebo LiDAR Plugin -->
  <gazebo reference="laser_link">
    <sensor name="lidar_sensor" type="ray">
      <always_on>true</always_on>
      <update_rate>10</update_rate>
      <visualize>true</visualize>
      <ray>
        <scan>
          <horizontal>
            <samples>720</samples>
            <resolution>1</resolution>
            <min_angle>-3.14159</min_angle>
            <max_angle>3.14159</max_angle>
          </horizontal>
        </scan>
        <range>
          <min>0.1</min>
          <max>30.0</max>
          <resolution>0.01</resolution>
        </range>
        <noise>
          <type>gaussian</type>
          <mean>0.0</mean>
          <stddev>0.01</stddev>
        </noise>
      </ray>
      <plugin name="gazebo_ros_laser_controller" filename="libgazebo_ros_ray_sensor.so">
        <ros>
          <namespace>/</namespace>
          <remapping>~/out:=scan</remapping>
        </ros>
        <output_type>sensor_msgs/LaserScan</output_type>
        <frame_name>laser_link</frame_name>
      </plugin>
    </sensor>
  </gazebo>

  <!-- Gazebo properties for better physics -->
  <gazebo reference="base_link">
    <material>Gazebo/Grey</material>
    <mu1>0.2</mu1>
    <mu2>0.2</mu2>
  </gazebo>

  <gazebo reference="front_left_wheel_link">
    <material>Gazebo/Black</material>
    <mu1>1.0</mu1>
    <mu2>1.0</mu2>
    <kp>1000000.0</kp>
    <kd>100.0</kd>
    <minDepth>0.001</minDepth>
  </gazebo>

  <gazebo reference="rear_left_wheel_link">
    <material>Gazebo/Black</material>
    <mu1>1.0</mu1>
    <mu2>1.0</mu2>
    <kp>1000000.0</kp>
    <kd>100.0</kd>
    <minDepth>0.001</minDepth>
  </gazebo>

  <gazebo reference="front_right_wheel_link">
    <material>Gazebo/Black</material>
    <mu1>1.0</mu1>
    <mu2>1.0</mu2>
    <kp>1000000.0</kp>
    <kd>100.0</kd>
    <minDepth>0.001</minDepth>
  </gazebo>

  <gazebo reference="rear_right_wheel_link">
    <material>Gazebo/Black</material>
    <mu1>1.0</mu1>
    <mu2>1.0</mu2>
    <kp>1000000.0</kp>
    <kd>100.0</kd>
    <minDepth>0.001</minDepth>
  </gazebo>

</robot>